# 错误处理机制

---

## **目录**

1.[Error 实例对象](#error实例对象)  

2.[原生错误类型](#原生错误类型)  

3.[自定义错误](#自定义错误)  

4.[throw语句](#throw语句)  

5.[try…catch结构](#trycatch)  

6.[finally代码块](#finally代码块)  

7.[以上三种方法的典型综合应用](#以上三种方法的典型综合应用)

# Error实例对象

 Error实例对象的属性：

 - message：表示出错的提示信息；
 - name：错误名称（非标准属性）
 - stack：错误的堆栈（非标准属性）
使用`name`和`message`这两个属性，可以对发生什么错误有一个大概的了解。

        if (error.name) {
          console.log(error.name + ': ' + error.message);
        }
`stack`属性用来查看错误发生时的堆栈。错误堆栈的最内层是`throwit`函数，然后是`catchit`函数，最后是函数的运行环境。


        function throwit() {
              throw new Error('');
            }
        function catchit() {
          try {
            throwit();
          } catch(e) {
            console.log(e.stack); // print stack trace
          }
        }
        
        catchit()
        // Error
        //    at throwit (~/examples/throwcatch.js:9:11)
        //    at catchit (~/examples/throwcatch.js:3:9)
        //    at repl:1:5

# 原生错误类型
Error实例对象是最一般的错误类型，在它的基础上，还存在Error的6个派生对象。
这6个派生对象，连同原始的Error对象，都是构造函数。这些构造函数都接受一个参数，代表错误提示信息。

 - SyntaxError对象 （句法）
 - ReferenceError对象 （引用）
 - RangeError对象 （界限）
 - TypeError对象 （类型）
 - URIError对象（）
 - EvalError对象（）

## 1. SyntaxError对象
是解析代码时发生的语法错误。
(1) 变量名错误

    var 1a;
    // Uncaught SyntaxError: Invalid or unexpected token

(2) 缺少括号

    console.log 'liboqing');
    SyntaxError: Unexpected string


## 2. ReferenceError对象
引用一个不存在的变量时发生的错误。
（1）使用一个不存在的变量。

    unknownVariable
    //ReferenceError: unknownVariable is not defined

（2）将一个值分配给无法匹配的对象，如对函数运行结果赋值。

    // 等号左侧不是变量
    console.log() = 1
    // ReferenceError: Invalid left-hand side in assignment

## 3. RangerError对象
值超出有效范围时发生的错误。
主要情况：
 1 数组长度为负数
 2 Number对象的方法参数超出范围

    // 数组长度不得为负数
    new Array(-1)
    // Uncaught RangeError: Invalid array length

## 4. TypeError对象
变量或参数不是预期类型时发生的错误。

字符串、布尔值、数值等原始类型的值的使用`new`命令，就会发生这正错误，因为`new`命令的参数应该是一个构造函数。

`new 123`
`//Number is not a constructor`

调用对象不存在的方法

`var obj = {};`
`obj.unknownMethod()`
`//TypeError: obj.unknownMethod is not a function`

## 5. URIError对象
URIError对象是URI相关函数不正确时抛出的错误，主要涉及以下六个函数：

 - encodeURI()
 - decodeURI()
 - encodeURIComponent()
 - decodeURIComponent()
 - escape()
 - unescape()

        decodeURI('%2')
        // URIError: URI malformed
     
        
## 6. EvalError对象
eval函数没有被正确执行时，会抛出EvalError错误，该错误类型已经不再使用了，只是为了保证与以前代码兼容，才继续保留。

# 自定义错误

    function UserError(message) {
      this.message = message || '默认信息';
      this.name = 'UserError';
    }
    
    UserError.prototype = new Error();
    UserError.prototype.constructor = UserError;

上面代码自定义一个错误对象UserError，让它继承Error对象。然后，就可以生成这种自定义类型的错误了。

    new UserError('这是自定义的错误！');

# throw语句
throw语句的作用是手动中断程序执行，抛出一个错误。
throw抛出的错误就是它的参数，他的**参数可以是任何值**。

实例1，基本应用：

    var x = -1;
    if (x <= 0) {
      throw new Error('x 必须为正数');
    }
    // Error: x 必须为正数

实例2，抛出自定义错误：

    function UserError(message) {
      this.message = message || '默认信息';
      this.name = 'UserError';
    }
    throw new UserError('出错了！');
    //UserError {message: "出错了！", name: "UserError"}

# try…Catch结构
### trycatch
允许对错误进行处理，选择是否往下继续执行。

    try {
      throw new Error('出错了!');
    } catch (e) {
      console.log(e.name + "--- " + e.message);
      console.log(e.stack);
    }
    // Error--- 出错了!
    // Error: 出错了!

上面代码中，try代码块抛出错误（上例用的是throw语句），JavaScript引擎就立即把代码的执行，转到catch代码块，或者说错误被catch代码块捕获了。catch接受一个参数，表示try代码块抛出的值。
不确定某些代码是否会报错时，就可以把它们放在try...catch代码块之中，便于进一步对错误进行处理。

甚至可以使用嵌套的try...catch结构。

为了捕捉不同类型的错误，catch代码块之中可以加入判断语句：

    try {
      foo.bar();
    } catch (e) {
      if (e instanceof EvalError) {
        console.log(e.name + ": " + e.message);
      } else if (e instanceof RangeError) {
        console.log(e.name + ": " + e.message);
      }
      // ...
    }
上面代码中，catch捕获错误之后，会判断错误类型（EvalError还是RangeError），进行不同的处理。


# finally代码块
上面的方法，如果没有catch语句块，一旦发生错误，代码就会中断执行。
而finally代码块的方法，会中断执行之前，先执行finally代码块，然后再向用户提示报错信息。

    var count = 0;
    function countUp() {
      try {
        return count;
      } finally {
        count++;
      }
    }
    
    countUp()
    // 0
    count
    // 1
这个实例中，return语句的执行是排在finally代码之前，只是等finally代码执行完毕后才返回。
return语句里面的count的值，是在finally代码块运行之前就获取了。

## 以上三种方法的典型综合应用

    openFile();
    
    try {
      writeFile(Data);
    } catch(e) {
      handleError(e);
    } finally {
      closeFile();
    }

上面代码首先打开一个文件，然后在try代码块中写入文件，如果没有发生错误，则运行finally代码块关闭文件；一旦发生错误，则先使用catch代码块处理错误，再使用finally代码块关闭文件。

----------


## try...catch...finally 三者执行顺序辨析

    function f() {
      try {
        console.log(0);
        throw 'bug';
      } catch(e) {
        console.log(1);
        return true; // 这句原本会延迟到 finally 代码块结束再执行
        console.log(2); // 不会运行
      } finally {
        console.log(3);
        return false; // 这句会覆盖掉前面那句 return
        console.log(4); // 不会运行
      }
    
      console.log(5); // 不会运行
    }
    
    var result = f();
    // 0
    // 1
    // 3
    
    result
    // false

上面代码中，catch代码块结束执行之前，会先执行finally代码块。注释写出了执行与否的原因。

----------


    function f() {
      try {
        throw '出错了！';
      } catch(e) {
        console.log('捕捉到内部错误');
        throw e; // 这句原本会等到finally结束再执行
      } finally {
        return false; // 直接返回
      }
    }
    
    try {
      f();
    } catch(e) {
      // 此处不会执行
      console.log('caught outer "bogus"');
    }
    
    //  捕捉到内部错误

上面代码中，进入catch代码块之后，一遇到throw语句，就会去执行finally代码块，其中有return false语句，因此就直接返回了，不再会回去执行catch代码块剩下的部分了。

----------


    try {
      try {
        consle.log('Hello world!'); // 报错
      }
      finally {
        console.log('Finally');
      }
      console.log('Will I run?');
    } catch(error) {
      console.error(error.message);
    }
    // Finally
    // consle is not defined

上面代码中，try里面还有一个try。内层的try报错（console拼错了），这时会执行内层的finally代码块，然后抛出错误，被外层的catch捕获。



[回到顶端](#错误处理机制)